Workbook

Sheet Bài 1
A1: Bài 1
A3: Thông số | B3: Giá trị
A4: Tỷ lệ chiết khấu r | B4: 0.17
A6: Dự án 1 – Bảng dòng tiền
A7: Năm | B7: Chi phí C_t | C7: Lợi ích B_t | D7: CF_t = B_t − C_t | E7: 1/(1+r)^t | F7: PV(CF_t) | G7: PV tích luỹ
A8: 0 | B8: 500 | C8: 0 | D8: =C8-B8 -> -500 | E8: =1/(1+$B$4)^A8 -> 1 | F8: =D8*E8 -> -500 | G8: =F8 -> -500
A9: 1 | B9: 0 | C9: 250 | D9: =C9-B9 -> 250 | E9: =1/(1+$B$4)^A9 -> 0.85470085 | F9: =D9*E9 -> 213.67521 | G9: =G8+F9 -> -286.32479
A10: 2 | B10: 100 | C10: 350 | D10: =C10-B10 -> 250 | E10: =1/(1+$B$4)^A10 -> 0.73051355 | F10: =D10*E10 -> 182.62839 | G10: =G9+F10 -> -103.6964
A11: 3 | B11: 0 | C11: 450 | D11: =C11-B11 -> 450 | E11: =1/(1+$B$4)^A11 -> 0.62437056 | F11: =D11*E11 -> 280.96675 | G11: =G10+F11 -> 177.27035
A12: 4 | B12: 0 | C12: 500 | D12: =C12-B12 -> 500 | E12: =1/(1+$B$4)^A12 -> 0.53365005 | F12: =D12*E12 -> 266.82502 | G12: =G11+F12 -> 444.09538
A13: 5 | B13: 0 | C13: -100 | D13: =C13-B13 -> -100 | E13: =1/(1+$B$4)^A13 -> 0.45611115 | F13: =D13*E13 -> -45.611115 | G13: =G12+F13 -> 398.48426
A15: KẾT QUẢ – Dự án 1
A16: Chỉ tiêu | B16: Ý nghĩa | C16: Kết quả
A17: PV(B) | B17: Tổng lợi ích quy về hiện tại | C17: =SUMPRODUCT(C8:C13,E8:E13) -> 971.53562
A18: PV(C) | B18: Tổng chi phí quy về hiện tại | C18: =SUMPRODUCT(B8:B13,E8:E13) -> 573.05136
A19: NPV (triệu) | B19: Giá trị hiện tại thuần | C19: =C17-C18 -> 398.48426
A20: NPV/PV(C) | B20: Lợi nhuận ròng trên 1 đồng vốn | C20: =C19/C18 -> 0.69537269
A21: BCR | B21: Tỷ số lợi ích/chi phí | C21: =C17/C18 -> 1.6953727
A22: IRR (%/năm) | B22: Lãi suất hoà vốn của dự án | C22: =IRR(D8:D13) -> 0.49560753
A23: Payback (năm) | B23: Thời gian hoàn vốn – không chiết khấu | C23: =_xlfn.LET(_xlpm.a,MATCH(TRUE,INDEX(G8:G13>=0,0),0)-1,IF(_xlpm.a<=0,0,_xlpm.a+ABS(INDEX(G8:G13,_xlpm.a+1))/INDEX(D8:D13,_xlpm.a+2))) -> 3.3545407
A24: Discounted Payback (năm) | B24: Thời gian hoàn vốn – có chiết khấu | C24: =_xlfn.LET(_xlpm.a,MATCH(TRUE,INDEX(G8:G13>=0,0),0)-1,IF(_xlpm.a<=0,0,_xlpm.a+ABS(INDEX(G8:G13,_xlpm.a+1))/INDEX(F8:F13,_xlpm.a+2))) -> 3.6643693
A27: Dự án 2 – Bảng dòng tiền
A28: Năm | B28: Chi phí C_t | C28: Lợi ích B_t | D28: CF_t | E28: 1/(1+r)^t | F28: PV(CF_t) | G28: PV tích luỹ
A29: 0 | B29: 100 | C29: 0 | D29: =C29-B29 -> -100 | E29: =1/(1+$B$4)^A29 -> 1 | F29: =D29*E29 -> -100 | G29: =F29 -> -100
A30: 1 | B30: 0 | C30: -100 | D30: =C30-B30 -> -100 | E30: =1/(1+$B$4)^A30 -> 0.85470085 | F30: =D30*E30 -> -85.470085 | G30: =G29+F30 -> -185.47009
A31: 2 | B31: 50 | C31: 200 | D31: =C31-B31 -> 150 | E31: =1/(1+$B$4)^A31 -> 0.73051355 | F31: =D31*E31 -> 109.57703 | G31: =G30+F31 -> -75.893053
A32: 3 | B32: 0 | C32: 200 | D32: =C32-B32 -> 200 | E32: =1/(1+$B$4)^A32 -> 0.62437056 | F32: =D32*E32 -> 124.87411 | G32: =G31+F32 -> 48.981058
A33: 4 | B33: 0 | C33: 200 | D33: =C33-B33 -> 200 | E33: =1/(1+$B$4)^A33 -> 0.53365005 | F33: =D33*E33 -> 106.73001 | G33: =G32+F33 -> 155.71107
A34: 5 | B34: 0 | C34: 300 | D34: =C34-B34 -> 300 | E34: =1/(1+$B$4)^A34 -> 0.45611115 | F34: =D34*E34 -> 136.83335 | G34: =G33+F34 -> 292.54441
A36: KẾT QUẢ – Dự án 2
A37: Chỉ tiêu | B37: Ý nghĩa | C37: Kết quả
A38: PV(B) | B38: Tổng lợi ích quy về hiện tại | C38: =SUMPRODUCT(C29:C34,E29:E34) -> 429.07009
A39: PV(C) | B39: Tổng chi phí quy về hiện tại | C39: =SUMPRODUCT(B29:B34,E29:E34) -> 136.52568
A40: NPV (triệu) | B40: Giá trị hiện tại thuần | C40: =C38-C39 -> 292.54441
A41: NPV/PV(C) | B41: Lợi nhuận ròng trên 1 đồng vốn | C41: =C40/C39 -> 2.1427794
A42: BCR | B42: Tỷ số lợi ích/chi phí | C42: =C38/C39 -> 3.1427794
A43: IRR (%/năm) | B43: Lãi suất hoà vốn của dự án | C43: =IRR(D29:D34) -> 0.61419858
A44: Payback (năm) | B44: Thời gian hoàn vốn – không chiết khấu | C44: =_xlfn.LET(_xlpm.a,MATCH(TRUE,INDEX(G29:G34>=0,0),0)-1,IF(_xlpm.a<=0,0,_xlpm.a+ABS(INDEX(G29:G34,_xlpm.a+1))/INDEX(D29:D34,_xlpm.a+2))) -> 3.2449053
A45: Discounted Payback (năm) | B45: Thời gian hoàn vốn – có chiết khấu | C45: =_xlfn.LET(_xlpm.a,MATCH(TRUE,INDEX(G29:G34>=0,0),0)-1,IF(_xlpm.a<=0,0,_xlpm.a+ABS(INDEX(G29:G34,_xlpm.a+1))/INDEX(F29:F34,_xlpm.a+2))) -> 3.4589249
A47: Tổng hợp
...

Sheet Bài 2
A1: Bài 2
A3: Thông số | B3: Giá trị
A4: Tỷ lệ chiết khấu r | B4: 0.18
A6: Dự án A – Bảng dòng tiền
A7: Năm | B7: Dòng vào | C7: Dòng ra | D7: CF_t = In − Out | E7: 1/(1+r)^t | F7: PV(CF_t) | G7: PV tích luỹ
A8: 0 | B8: 0 | C8: 225 | D8: =B8-C8 -> -225 | E8: =1/(1+$B$4)^A8 -> 1 | F8: =D8*E8 -> -225 | G8: =F8 -> -225
A9: 1 | B9: 0 | C9: 190 | D9: =B9-C9 -> -190 | E9: =1/(1+$B$4)^A9 -> 0.84745763 | F9: =D9*E9 -> -161.01695 | G9: =G8+F9 -> -386.01695
A10: 2 | B10: 150 | C10: 0 | D10: =B10-C10 -> 150 | E10: =1/(1+$B$4)^A10 -> 0.71818443 | F10: =D10*E10 -> 107.72766 | G10: =G9+F10 -> -278.28928
A11: 3 | B11: 220 | C11: 30 | D11: =B11-C11 -> 190 | E11: =1/(1+$B$4)^A11 -> 0.60863087 | F11: =D11*E11 -> 115.63987 | G11: =G10+F11 -> -162.64942
A12: 4 | B12: 215 | C12: 0 | D12: =B12-C12 -> 215 | E12: =1/(1+$B$4)^A12 -> 0.51578888 | F12: =D12*E12 -> 110.89461 | G12: =G11+F12 -> -51.754811
A13: 5 | B13: 205 | C13: 30 | D13: =B13-C13 -> 175 | E13: =1/(1+$B$4)^A13 -> 0.43710922 | F13: =D13*E13 -> 76.494113 | G13: =G12+F13 -> 24.739302
A14: 6 | B14: 197 | C14: 0 | D14: =B14-C14 -> 197 | E14: =1/(1+$B$4)^A14 -> 0.37043154 | F14: =D14*E14 -> 72.975013 | G14: =G13+F14 -> 97.714315
A15: 7 | B15: 100 | C15: 30 | D15: =B15-C15 -> 70 | E15: =1/(1+$B$4)^A15 -> 0.31392503 | F15: =D15*E15 -> 21.974752 | G15: =G14+F15 -> 119.68907
A17: KẾT QUẢ – Dự án A
A18: Chỉ tiêu | B18: Ý nghĩa | C18: Kết quả
A19: PV(Dòng vào) | B19: Tổng inflow quy hiện tại | C19: =SUMPRODUCT(B8:B15,E8:E15) -> 546.49597
A20: PV(Dòng ra) | B20: Tổng outflow quy hiện tại | C20: =SUMPRODUCT(C8:C15,E8:E15) -> 426.8069
A21: NPV (triệu) | B21: Giá trị hiện tại thuần | C21: =C19-C20 -> 119.68907
A22: NPV/PV(Out) | B22: Lợi nhuận ròng/1 đồng outflow | C22: =C21/C20 -> 0.28042908
A23: BCR | B23: Tỷ số lợi ích/chi phí | C23: =C19/C20 -> 1.2804291
A24: IRR (%/năm) | B24: Lãi suất hoà vốn | C24: =IRR(D8:D15) -> 0.27688389
A25: Payback (năm) | B25: Hoàn vốn – không chiết khấu | C25: =_xlfn.LET(_xlpm.a,MATCH(TRUE,INDEX(G8:G15>=0,0),0)-1,IF(_xlpm.a<=0,0,_xlpm.a+ABS(INDEX(G8:G15,_xlpm.a+1))/INDEX(D8:D15,_xlpm.a+2))) -> 5.1255802
A26: Discounted Payback (năm) | B26: Hoàn vốn – có chiết khấu | C26: =_xlfn.LET(_xlpm.a,MATCH(TRUE,INDEX(G8:G15>=0,0),0)-1,IF(_xlpm.a<=0,0,_xlpm.a+ABS(INDEX(G8:G15,_xlpm.a+1))/INDEX(F8:F15,_xlpm.a+2))) -> 5.3390106
A29: Dự án B – Bảng dòng tiền
A30: Năm | B30: Dòng vào | C30: Dòng ra | D30: CF_t = In − Out | E30: 1/(1+r)^t | F30: PV(CF_t) | G30: PV tích luỹ
A31: 0 | B31: 0 | C31: 300 | D31: =B31-C31 -> -300 | E31: =1/(1+$B$4)^A31 -> 1 | F31: =D31*E31 -> -300 | G31: =F31 -> -300
A32: 1 | B32: 50 | C32: 100 | D32: =B32-C32 -> -50 | E32: =1/(1+$B$4)^A32 -> 0.84745763 | F32: =D32*E32 -> -42.372881 | G32: =G31+F32 -> -342.37288
A33: 2 | B33: 150 | C33: 0 | D33: =B33-C33 -> 150 | E33: =1/(1+$B$4)^A33 -> 0.71818443 | F33: =D33*E33 -> 107.72766 | G33: =G32+F33 -> -234.64522
A34: 3 | B34: 250 | C34: 0 | D34: =B34-C34 -> 250 | E34: =1/(1+$B$4)^A34 -> 0.60863087 | F34: =D34*E34 -> 152.15772 | G34: =G33+F34 -> -82.487499
A35: 4 | B35: 250 | C35: 50 | D35: =B35-C35 -> 200 | E35: =1/(1+$B$4)^A35 -> 0.51578888 | F35: =D35*E35 -> 103.15778 | G35: =G34+F35 -> 20.670276
A36: 5 | B36: 200 | C36: 0 | D36: =B36-C36 -> 200 | E36: =1/(1+$B$4)^A36 -> 0.43710922 | F36: =D36*E36 -> 87.421843 | G36: =G35+F36 -> 108.09212
A37: 6 | B37: 180 | C37: 0 | D37: =B37-C37 -> 180 | E37: =1/(1+$B$4)^A37 -> 0.37043154 | F37: =D37*E37 -> 66.677677 | G37: =G36+F37 -> 174.7698
A38: 7 | B38: 120 | C38: 50 | D38: =B38-C38 -> 70 | E38: =1/(1+$B$4)^A38 -> 0.31392503 | F38: =D38*E38 -> 21.974752 | G38: =G37+F38 -> 196.74455
A40: KẾT QUẢ – Dự án B
A41: Chỉ tiêu | B41: Ý nghĩa | C41: Kết quả
A42: PV(Dòng vào) | B42: Tổng inflow quy hiện tại | C42: =SUMPRODUCT(B31:B38,E31:E38) -> 622.97601
A43: PV(Dòng ra) | B43: Tổng outflow quy hiện tại | C43: =SUMPRODUCT(C31:C38,E31:E38) -> 426.23146
A44: NPV (triệu) | B44: Giá trị hiện tại thuần | C44: =C42-C43 -> 196.74455
A45: NPV/PV(Out) | B45: Lợi nhuận ròng/1 đồng outflow | C45: =C44/C43 -> 0.46159087
A46: BCR | B46: Tỷ số lợi ích/chi phí | C46: =C42/C43 -> 1.4615909
...

Sheet Bài 3
A1: Bài 3
A3: Dự án | B3: Chi phí đầu tư | C3: Dòng tiền ròng hàng năm
A4: A | B4: 150000 | C4: 40000
A5: B | B5: 200000 | C5: 50000
A7: KẾT QUẢ CUỐI
A8: Chỉ tiêu | B8: Ý nghĩa | C8: Kết quả
A9: Payback – Dự án A | B9: Số năm hoàn vốn (không chiết khấu) | C9: =B4/C4 -> 3.75
A10: Payback – Dự án B | B10: Số năm hoàn vốn (không chiết khấu) | C10: =B5/C5 -> 4

Sheet Bài 4
A1: Bài 4
A3: Thông số | B3: Giá trị
A4: r | B4: 0.1
A6: Năm | B6: CF_t ($) | C6: 1/(1+r)^t | D6: PV(CF_t) | E6: PV tích luỹ | F6: Đánh dấu cross
A7: 1 | B7: 1000 | C7: =1/(1+$B$4)^A7 -> 0.90909091 | D7: =B7*C7 -> 909.09091 | E7: =-5000+D7 -> -4090.9091 | F7: =IF(AND(E7<0,E8>=0),"cross","")
A8: 2 | B8: 1000 | C8: =1/(1+$B$4)^A8 -> 0.82644628 | D8: =B8*C8 -> 826.44628 | E8: =E7+D8 -> -3264.4628 | F8: =IF(AND(E8<0,E9>=0),"cross","")
A9: 3 | B9: 1000 | C9: =1/(1+$B$4)^A9 -> 0.7513148 | D9: =B9*C9 -> 751.3148 | E9: =E8+D9 -> -2513.148 | F9: =IF(AND(E9<0,E10>=0),"cross","")
A10: 4 | B10: 1000 | C10: =1/(1+$B$4)^A10 -> 0.68301346 | D10: =B10*C10 -> 683.01346 | E10: =E9+D10 -> -1830.1346 | F10: =IF(AND(E10<0,E11>=0),"cross","")
A11: 5 | B11: 1000 | C11: =1/(1+$B$4)^A11 -> 0.62092132 | D11: =B11*C11 -> 620.92132 | E11: =E10+D11 -> -1209.2132 | F11: =IF(AND(E11<0,E12>=0),"cross","")
A12: 6 | B12: 1000 | C12: =1/(1+$B$4)^A12 -> 0.56447393 | D12: =B12*C12 -> 564.47393 | E12: =E11+D12 -> -644.7393 | F12: =IF(AND(E12<0,E13>=0),"cross","")
A13: 7 | B13: 1000 | C13: =1/(1+$B$4)^A13 -> 0.51315812 | D13: =B13*C13 -> 513.15812 | E13: =E12+D13 -> -131.58118 | F13: =IF(AND(E13<0,E14>=0),"cross","") -> cross
A14: 8 | B14: 1000 | C14: =1/(1+$B$4)^A14 -> 0.46650738 | D14: =B14*C14 -> 466.50738 | E14: =E13+D14 -> 334.9262 | F14: =IF(AND(E14<0,E15>=0),"cross","")
A15: 9 | B15: 1000 | C15: =1/(1+$B$4)^A15 -> 0.42409762 | D15: =B15*C15 -> 424.09762 | E15: =E14+D15 -> 759.02382 | F15: =IF(AND(E15<0,E16>=0),"cross","")
A16: 10 | B16: 1000 | C16: =1/(1+$B$4)^A16 -> 0.38554329 | D16: =B16*C16 -> 385.54329 | E16: =E15+D16 -> 1144.5671 | F16: =IF(AND(E16<0,E17>=0),"cross","")
A17: 11 | B17: 1000 | C17: =1/(1+$B$4)^A17 -> 0.3504939 | D17: =B17*C17 -> 350.4939 | E17: =E16+D17 -> 1495.061 | F17: =IF(AND(E17<0,E18>=0),"cross","")
A18: 12 | B18: 1000 | C18: =1/(1+$B$4)^A18 -> 0.31863082 | D18: =B18*C18 -> 318.63082 | E18: =E17+D18 -> 1813.6918 | F18: =IF(AND(E18<0,E19>=0),"cross","")
A19: 13 | B19: 1000 | C19: =1/(1+$B$4)^A19 -> 0.28966438 | D19: =B19*C19 -> 289.66438 | E19: =E18+D19 -> 2103.3562 | F19: =IF(AND(E19<0,E20>=0),"cross","")
A20: 14 | B20: 1000 | C20: =1/(1+$B$4)^A20 -> 0.26333125 | D20: =B20*C20 -> 263.33125 | E20: =E19+D20 -> 2366.6875 | F20: =IF(AND(E20<0,E21>=0),"cross","")
A21: 15 | B21: 1000 | C21: =1/(1+$B$4)^A21 -> 0.23939205 | D21: =B21*C21 -> 239.39205 | E21: =E20+D21 -> 2606.0795
A23: KẾT QUẢ
A24: Chỉ tiêu | B24: Ý nghĩa | C24: Kết quả
A25: Discounted Payback (năm) | B25: Số năm để PV tích luỹ = 0 | C25: =INDEX(A7:A21,MATCH("cross",F7:F21,0))+ABS(INDEX(E7:E21,MATCH("cross",F7:F21,0)))/INDEX(D7:D21,MATCH("cross",F7:F21,0)+1) -> 7.282056

Sheet Bài 5
A1: Bài 5
A3: Thông số | B3: Giá trị
A4: r | B4: 0.17
A6: t | B6: CF_t | C6: 1/(1+r)^t | D6: PV(CF_t) | E6: PV tích luỹ | F6: Đánh dấu cross
A7: 0 | B7: -100 | C7: =1/(1+$B$4)^A7 -> 1 | D7: =B7*C7 -> -100 | E7: =D7 -> -100 | F7: =IF(AND(E7<0,E8>=0),"cross","")
A8: 1 | B8: 30 | C8: =1/(1+$B$4)^A8 -> 0.85470085 | D8: =B8*C8 -> 25.641026 | E8: =E7+D8 -> -74.358974 | F8: =IF(AND(E8<0,E9>=0),"cross","")
A9: 2 | B9: 30 | C9: =1/(1+$B$4)^A9 -> 0.73051355 | D9: =B9*C9 -> 21.915407 | E9: =E8+D9 -> -52.443568 | F9: =IF(AND(E9<0,E10>=0),"cross","")
A10: 3 | B10: 30 | C10: =1/(1+$B$4)^A10 -> 0.62437056 | D10: =B10*C10 -> 18.731117 | E10: =E9+D10 -> -33.712451 | F10: =IF(AND(E10<0,E11>=0),"cross","")
A11: 4 | B11: 40 | C11: =1/(1+$B$4)^A11 -> 0.53365005 | D11: =B11*C11 -> 21.346002 | E11: =E10+D11 -> -12.366449 | F11: =IF(AND(E11<0,E12>=0),"cross","") -> cross
A12: 5 | B12: 40 | C12: =1/(1+$B$4)^A12 -> 0.45611115 | D12: =B12*C12 -> 18.244446 | E12: =E11+D12 -> 5.8779969
A14: KẾT QUẢ
A15: Chỉ tiêu | B15: Ý nghĩa | C15: Kết quả
A16: Discounted Payback (năm) | B16: Số năm để PV tích luỹ = 0 | C16: =INDEX(A7:A12,MATCH("cross",F7:F12,0))+ABS(INDEX(E7:E12,MATCH("cross",F7:F12,0)))/INDEX(D7:D12,MATCH("cross",F7:F12,0)+1) -> 4.6778199

Sheet Bài 6
A1: Bài 6
A3: Khoản mục | B3: Mốc thời gian | C3: Quy đổi về cuối năm 3 | D3: Ghi chú
A4: 100 | B4: Năm 2 | C4: =A4*(1+0.17) -> 117 | D4: Vốn hoá 1 năm
A5: 300 | B5: Năm 5 | C5: =A5/(1+0.17)^2 -> 219.15407 | D5: Chiết khấu 2 năm
A7: KẾT QỦA
A8: Chỉ tiêu | B8: Ý nghĩa | C8: Kết quả
A9: Số tiền tất toán (triệu) | B9: Chi trả 1 lần tại cuối năm 3 | C9: =C4+C5 -> 336.15407

Sheet Bài 7
A1: Bài 7
A3: Tiêu chí | B3: Nhà tài trợ mạnh | C3: Hỗ trợ chiến lược KD | D3: Tính cấp thiết | E3: 10% doanh số SP mới | F3: Cạnh tranh | G3: Lấp đầy khoảng trống TT | H3: Tổng trọng số
A4: Trọng số | B4: 2 | C4: 5 | D4: 4 | E4: 3 | F4: 1 | G4: 3 | H4: =SUM(B4:G4) -> 18
A6: Dự án | B6: Nhà tài trợ mạnh | C6: Hỗ trợ chiến lược KD | D6: Tính cấp thiết | E6: 10% doanh số SP mới | F6: Cạnh tranh | G6: Lấp đầy khoảng trống TT | H6: Tổng điểm có trọng số
A7: Dự án 1 | B7: 9 | C7: 5 | D7: 2 | E7: 0 | F7: 2 | G7: 5 | H7: =SUMPRODUCT(B7:G7,B4:G4) -> 68
A8: Dự án 2 | B8: 2 | C8: 6 | D8: 2 | E8: 1 | F8: 5 | G8: 1 | H8: =SUMPRODUCT(B8:G8,B4:G4) -> 53
A9: Dự án 3 | B9: 6 | C9: 8 | D9: 9 | E9: 6 | F9: 2 | G9: 5 | H9: =SUMPRODUCT(B9:G9,B4:G4) -> 123
A10: Dự án 4 | B10: 1 | C10: 4 | D10: 2 | E10: 10 | F10: 5 | G10: 1 | H10: =SUMPRODUCT(B10:G10,B4:G4) -> 68
A11: Dự án 5 | B11: 3 | C11: 10 | D11: 9 | E11: 10 | F11: 2 | G11: 8 | H11: =SUMPRODUCT(B11:G11,B4:G4) -> 148
A13: KẾT QUẢ
A14: Chỉ tiêu | B14: Ý nghĩa | C14: Kết quả
A15: Dự án cao nhất | B15: Theo tổng điểm có trọng số | C15: =INDEX(A7:A11,MATCH(MAX(H7:H11),H7:H11,0)) -> Dự án 5
A16: Dự án thấp nhất | B16: Theo tổng điểm có trọng số | C16: =INDEX(A7:A11,MATCH(MIN(H7:H11),H7:H11,0)) -> Dự án 2

Sheet Bài 8
A1: Bài 8
A3: Ký hiệu | B3: Giá trị | C3: Mô tả
A4: A | B4: 25 | C4: Khoản trả mỗi tháng
A5: n | B5: 12 | C5: Số tháng
A6: i | B6: 0.015 | C6: Lãi suất/tháng
A8: KẾT QUẢ
A9: Chỉ tiêu | B9: Ý nghĩa | C9: Kết quả
A10: PV (triệu) | B10: Tiền trả ngay tương đương | C10: =B4*((1-(1+B6)^(-B5))/B6) -> 272.68763

Sheet Bài 9
A1: Bài 9
A3: Tham số | B3: Giá trị | C3: Mô tả
A4: P | B4: 100 | C4: Gốc ban đầu (triệu)
A5: i | B5: 0.12 | C5: Lãi suất năm
A6: k | B6: 7 | C6: Số kỳ đã trả
A7: A_cũ | B7: 10 | C7: Trả mỗi năm hiện tại (triệu)
A8: m | B8: 5 | C8: Số năm muốn trả tiếp
A10: Bảng hệ số
A11: Bước tính | B11: Công thức | C11: Giá trị
A12: (1+i)^k | B12: =(1+$B$5)^$B$6 -> 2.2106814 | C12: =(1+$B$5)^$B$6 -> 2.2106814
A13: a_k=((1+i)^k-1)/i | B13: =((1+$B$5)^$B$6-1)/$B$5 -> 10.089012 | C13: =((1+$B$5)^$B$6-1)/$B$5 -> 10.089012
A14: Dư nợ B_k | B14: =$B$4*C12-$B$7*C13 -> 120.17802 | C14: =$B$4*C12-$B$7*C13 -> 120.17802
A15: a_m=((1+i)^m-1)/(i(1+i)^m) | B15: =((1+$B$5)^$B$8-1)/($B$5*(1+$B$5)^$B$8) -> 3.6047762 | C15: =((1+$B$5)^$B$8-1)/($B$5*(1+$B$5)^$B$8) -> 3.6047762
A17: KẾT QUẢ
A18: Chỉ tiêu | B18: Ý nghĩa | C18: Kết quả
A19: Dư nợ còn lại sau 7 kỳ (triệu) | B19: Giá trị tại thời điểm sau kỳ thứ 7 | C19: =C14 -> 120.17802
A20: Khoản trả mới X (triệu/năm) | B20: Dàn đều trong 5 năm để PV nghĩa vụ = Dư nợ còn lại | C20: =C14/C15 -> 33.338553
